[2025-05-24T22:16:46.892+0000] {local_task_job_runner.py:120} INFO - ::group::Pre task execution logs
[2025-05-24T22:16:46.905+0000] {taskinstance.py:2073} INFO - Dependencies all met for dep_context=non-requeueable deps ti=<TaskInstance: supplier_data_etl_pipeline.extract_sql_data manual__2025-05-24T21:29:11.201967+00:00 [queued]>
[2025-05-24T22:16:46.910+0000] {taskinstance.py:2073} INFO - Dependencies all met for dep_context=requeueable deps ti=<TaskInstance: supplier_data_etl_pipeline.extract_sql_data manual__2025-05-24T21:29:11.201967+00:00 [queued]>
[2025-05-24T22:16:46.910+0000] {taskinstance.py:2303} INFO - Starting attempt 10 of 11
[2025-05-24T22:16:46.919+0000] {taskinstance.py:2327} INFO - Executing <Task(PythonOperator): extract_sql_data> on 2025-05-24 21:29:11.201967+00:00
[2025-05-24T22:16:46.925+0000] {warnings.py:110} WARNING - /home/***/.local/lib/python3.12/site-packages/***/task/task_runner/standard_task_runner.py:61: DeprecationWarning: This process (pid=1518) is multi-threaded, use of fork() may lead to deadlocks in the child.
  pid = os.fork()

[2025-05-24T22:16:46.928+0000] {standard_task_runner.py:63} INFO - Started process 1520 to run task
[2025-05-24T22:16:46.929+0000] {standard_task_runner.py:90} INFO - Running: ['***', 'tasks', 'run', 'supplier_data_etl_pipeline', 'extract_sql_data', 'manual__2025-05-24T21:29:11.201967+00:00', '--job-id', '118', '--raw', '--subdir', 'DAGS_FOLDER/supplier_dag.py', '--cfg-path', '/tmp/tmpfqxat1ei']
[2025-05-24T22:16:46.930+0000] {standard_task_runner.py:91} INFO - Job 118: Subtask extract_sql_data
[2025-05-24T22:16:46.991+0000] {task_command.py:426} INFO - Running <TaskInstance: supplier_data_etl_pipeline.extract_sql_data manual__2025-05-24T21:29:11.201967+00:00 [running]> on host a7d211f7b093
[2025-05-24T22:16:47.088+0000] {taskinstance.py:2644} INFO - Exporting env vars: AIRFLOW_CTX_DAG_OWNER='***' AIRFLOW_CTX_DAG_ID='supplier_data_etl_pipeline' AIRFLOW_CTX_TASK_ID='extract_sql_data' AIRFLOW_CTX_EXECUTION_DATE='2025-05-24T21:29:11.201967+00:00' AIRFLOW_CTX_TRY_NUMBER='10' AIRFLOW_CTX_DAG_RUN_ID='manual__2025-05-24T21:29:11.201967+00:00'
[2025-05-24T22:16:47.091+0000] {taskinstance.py:430} INFO - ::endgroup::
[2025-05-24T22:16:47.094+0000] {etl.py:77} INFO - connected to db source
[2025-05-24T22:16:47.097+0000] {taskinstance.py:441} INFO - ::group::Post task execution logs
[2025-05-24T22:16:47.098+0000] {taskinstance.py:2890} ERROR - Task failed with exception
Traceback (most recent call last):
  File "/home/airflow/.local/lib/python3.12/site-packages/pandas/io/sql.py", line 2674, in execute
    cur.execute(sql, *args)
sqlite3.OperationalError: no such table: supplier_records

The above exception was the direct cause of the following exception:

Traceback (most recent call last):
  File "/home/airflow/.local/lib/python3.12/site-packages/airflow/models/taskinstance.py", line 465, in _execute_task
    result = _execute_callable(context=context, **execute_callable_kwargs)
             ^^^^^^^^^^^^^^^^^^^^^^^^^^^^^^^^^^^^^^^^^^^^^^^^^^^^^^^^^^^^^
  File "/home/airflow/.local/lib/python3.12/site-packages/airflow/models/taskinstance.py", line 432, in _execute_callable
    return execute_callable(context=context, **execute_callable_kwargs)
           ^^^^^^^^^^^^^^^^^^^^^^^^^^^^^^^^^^^^^^^^^^^^^^^^^^^^^^^^^^^^
  File "/home/airflow/.local/lib/python3.12/site-packages/airflow/models/baseoperator.py", line 400, in wrapper
    return func(self, *args, **kwargs)
           ^^^^^^^^^^^^^^^^^^^^^^^^^^^
  File "/home/airflow/.local/lib/python3.12/site-packages/airflow/operators/python.py", line 235, in execute
    return_value = self.execute_callable()
                   ^^^^^^^^^^^^^^^^^^^^^^^
  File "/home/airflow/.local/lib/python3.12/site-packages/airflow/operators/python.py", line 252, in execute_callable
    return self.python_callable(*self.op_args, **self.op_kwargs)
           ^^^^^^^^^^^^^^^^^^^^^^^^^^^^^^^^^^^^^^^^^^^^^^^^^^^^^
  File "/opt/airflow/dags/etl.py", line 78, in extract_sql
    df = pd.read_sql_query("SELECT * FROM supplier_records", conn)
         ^^^^^^^^^^^^^^^^^^^^^^^^^^^^^^^^^^^^^^^^^^^^^^^^^^^^^^^^^
  File "/home/airflow/.local/lib/python3.12/site-packages/pandas/io/sql.py", line 526, in read_sql_query
    return pandas_sql.read_query(
           ^^^^^^^^^^^^^^^^^^^^^^
  File "/home/airflow/.local/lib/python3.12/site-packages/pandas/io/sql.py", line 2738, in read_query
    cursor = self.execute(sql, params)
             ^^^^^^^^^^^^^^^^^^^^^^^^^
  File "/home/airflow/.local/lib/python3.12/site-packages/pandas/io/sql.py", line 2686, in execute
    raise ex from exc
pandas.errors.DatabaseError: Execution failed on sql 'SELECT * FROM supplier_records': no such table: supplier_records
[2025-05-24T22:16:47.113+0000] {taskinstance.py:1205} INFO - Marking task as UP_FOR_RETRY. dag_id=supplier_data_etl_pipeline, task_id=extract_sql_data, execution_date=20250524T212911, start_date=20250524T221646, end_date=20250524T221647
[2025-05-24T22:16:47.123+0000] {standard_task_runner.py:110} ERROR - Failed to execute job 118 for task extract_sql_data (Execution failed on sql 'SELECT * FROM supplier_records': no such table: supplier_records; 1520)
[2025-05-24T22:16:47.163+0000] {local_task_job_runner.py:240} INFO - Task exited with return code 1
[2025-05-24T22:16:47.179+0000] {taskinstance.py:3482} INFO - 0 downstream tasks scheduled from follow-on schedule check
[2025-05-24T22:16:47.180+0000] {local_task_job_runner.py:222} INFO - ::endgroup::
