[2025-05-24T22:54:44.463+0000] {local_task_job_runner.py:120} INFO - ::group::Pre task execution logs
[2025-05-24T22:54:44.488+0000] {taskinstance.py:2073} INFO - Dependencies all met for dep_context=non-requeueable deps ti=<TaskInstance: supplier_data_etl_pipeline.upload_merged_to_s3 manual__2025-05-24T22:54:15.604677+00:00 [queued]>
[2025-05-24T22:54:44.495+0000] {taskinstance.py:2073} INFO - Dependencies all met for dep_context=requeueable deps ti=<TaskInstance: supplier_data_etl_pipeline.upload_merged_to_s3 manual__2025-05-24T22:54:15.604677+00:00 [queued]>
[2025-05-24T22:54:44.495+0000] {taskinstance.py:2303} INFO - Starting attempt 1 of 6
[2025-05-24T22:54:44.504+0000] {taskinstance.py:2327} INFO - Executing <Task(PythonOperator): upload_merged_to_s3> on 2025-05-24 22:54:15.604677+00:00
[2025-05-24T22:54:44.513+0000] {warnings.py:110} WARNING - /home/***/.local/lib/python3.12/site-packages/***/task/task_runner/standard_task_runner.py:61: DeprecationWarning: This process (pid=2184) is multi-threaded, use of fork() may lead to deadlocks in the child.
  pid = os.fork()

[2025-05-24T22:54:44.515+0000] {standard_task_runner.py:63} INFO - Started process 2186 to run task
[2025-05-24T22:54:44.516+0000] {standard_task_runner.py:90} INFO - Running: ['***', 'tasks', 'run', 'supplier_data_etl_pipeline', 'upload_merged_to_s3', 'manual__2025-05-24T22:54:15.604677+00:00', '--job-id', '178', '--raw', '--subdir', 'DAGS_FOLDER/supplier_dag.py', '--cfg-path', '/tmp/tmpgjcjwdsc']
[2025-05-24T22:54:44.518+0000] {standard_task_runner.py:91} INFO - Job 178: Subtask upload_merged_to_s3
[2025-05-24T22:54:44.564+0000] {task_command.py:426} INFO - Running <TaskInstance: supplier_data_etl_pipeline.upload_merged_to_s3 manual__2025-05-24T22:54:15.604677+00:00 [running]> on host a7d211f7b093
[2025-05-24T22:54:44.636+0000] {taskinstance.py:2644} INFO - Exporting env vars: AIRFLOW_CTX_DAG_OWNER='***' AIRFLOW_CTX_DAG_ID='supplier_data_etl_pipeline' AIRFLOW_CTX_TASK_ID='upload_merged_to_s3' AIRFLOW_CTX_EXECUTION_DATE='2025-05-24T22:54:15.604677+00:00' AIRFLOW_CTX_TRY_NUMBER='1' AIRFLOW_CTX_DAG_RUN_ID='manual__2025-05-24T22:54:15.604677+00:00'
[2025-05-24T22:54:44.638+0000] {taskinstance.py:430} INFO - ::endgroup::
[2025-05-24T22:54:44.652+0000] {etl.py:167} ERROR - Unexpected error during S3 upload: 'Variable access_key does not exist'
[2025-05-24T22:54:44.652+0000] {taskinstance.py:441} INFO - ::group::Post task execution logs
[2025-05-24T22:54:44.653+0000] {taskinstance.py:2890} ERROR - Task failed with exception
Traceback (most recent call last):
  File "/home/airflow/.local/lib/python3.12/site-packages/airflow/models/taskinstance.py", line 465, in _execute_task
    result = _execute_callable(context=context, **execute_callable_kwargs)
             ^^^^^^^^^^^^^^^^^^^^^^^^^^^^^^^^^^^^^^^^^^^^^^^^^^^^^^^^^^^^^
  File "/home/airflow/.local/lib/python3.12/site-packages/airflow/models/taskinstance.py", line 432, in _execute_callable
    return execute_callable(context=context, **execute_callable_kwargs)
           ^^^^^^^^^^^^^^^^^^^^^^^^^^^^^^^^^^^^^^^^^^^^^^^^^^^^^^^^^^^^
  File "/home/airflow/.local/lib/python3.12/site-packages/airflow/models/baseoperator.py", line 400, in wrapper
    return func(self, *args, **kwargs)
           ^^^^^^^^^^^^^^^^^^^^^^^^^^^
  File "/home/airflow/.local/lib/python3.12/site-packages/airflow/operators/python.py", line 235, in execute
    return_value = self.execute_callable()
                   ^^^^^^^^^^^^^^^^^^^^^^^
  File "/home/airflow/.local/lib/python3.12/site-packages/airflow/operators/python.py", line 252, in execute_callable
    return self.python_callable(*self.op_args, **self.op_kwargs)
           ^^^^^^^^^^^^^^^^^^^^^^^^^^^^^^^^^^^^^^^^^^^^^^^^^^^^^
  File "/opt/airflow/dags/etl.py", line 144, in upload_to_s3
    s3 = boto3_client("s3")
         ^^^^^^^^^^^^^^^^^^
  File "/opt/airflow/dags/etl.py", line 133, in boto3_client
    aws_access_key_id=Variable.get('access_key'),
                      ^^^^^^^^^^^^^^^^^^^^^^^^^^
  File "/home/airflow/.local/lib/python3.12/site-packages/airflow/models/variable.py", line 143, in get
    raise KeyError(f"Variable {key} does not exist")
KeyError: 'Variable access_key does not exist'
[2025-05-24T22:54:44.665+0000] {taskinstance.py:1205} INFO - Marking task as UP_FOR_RETRY. dag_id=supplier_data_etl_pipeline, task_id=upload_merged_to_s3, execution_date=20250524T225415, start_date=20250524T225444, end_date=20250524T225444
[2025-05-24T22:54:44.678+0000] {standard_task_runner.py:110} ERROR - Failed to execute job 178 for task upload_merged_to_s3 ('Variable access_key does not exist'; 2186)
[2025-05-24T22:54:44.698+0000] {local_task_job_runner.py:240} INFO - Task exited with return code 1
[2025-05-24T22:54:44.716+0000] {taskinstance.py:3482} INFO - 0 downstream tasks scheduled from follow-on schedule check
[2025-05-24T22:54:44.717+0000] {local_task_job_runner.py:222} INFO - ::endgroup::
