[2025-05-24T21:03:22.498+0000] {local_task_job_runner.py:120} INFO - ::group::Pre task execution logs
[2025-05-24T21:03:22.520+0000] {taskinstance.py:2073} INFO - Dependencies all met for dep_context=non-requeueable deps ti=<TaskInstance: supplier_data_etl_pipeline.extract_sql_data manual__2025-05-24T21:03:17.340189+00:00 [queued]>
[2025-05-24T21:03:22.526+0000] {taskinstance.py:2073} INFO - Dependencies all met for dep_context=requeueable deps ti=<TaskInstance: supplier_data_etl_pipeline.extract_sql_data manual__2025-05-24T21:03:17.340189+00:00 [queued]>
[2025-05-24T21:03:22.527+0000] {taskinstance.py:2303} INFO - Starting attempt 1 of 2
[2025-05-24T21:03:22.539+0000] {taskinstance.py:2327} INFO - Executing <Task(PythonOperator): extract_sql_data> on 2025-05-24 21:03:17.340189+00:00
[2025-05-24T21:03:22.551+0000] {warnings.py:110} WARNING - /home/***/.local/lib/python3.12/site-packages/***/task/task_runner/standard_task_runner.py:61: DeprecationWarning: This process (pid=307) is multi-threaded, use of fork() may lead to deadlocks in the child.
  pid = os.fork()

[2025-05-24T21:03:22.553+0000] {standard_task_runner.py:63} INFO - Started process 318 to run task
[2025-05-24T21:03:22.553+0000] {standard_task_runner.py:90} INFO - Running: ['***', 'tasks', 'run', 'supplier_data_etl_pipeline', 'extract_sql_data', 'manual__2025-05-24T21:03:17.340189+00:00', '--job-id', '3', '--raw', '--subdir', 'DAGS_FOLDER/supplier_dag.py', '--cfg-path', '/tmp/tmp33mqdd65']
[2025-05-24T21:03:22.555+0000] {standard_task_runner.py:91} INFO - Job 3: Subtask extract_sql_data
[2025-05-24T21:03:22.641+0000] {task_command.py:426} INFO - Running <TaskInstance: supplier_data_etl_pipeline.extract_sql_data manual__2025-05-24T21:03:17.340189+00:00 [running]> on host a7d211f7b093
[2025-05-24T21:03:22.757+0000] {taskinstance.py:2644} INFO - Exporting env vars: AIRFLOW_CTX_DAG_OWNER='***' AIRFLOW_CTX_DAG_ID='supplier_data_etl_pipeline' AIRFLOW_CTX_TASK_ID='extract_sql_data' AIRFLOW_CTX_EXECUTION_DATE='2025-05-24T21:03:17.340189+00:00' AIRFLOW_CTX_TRY_NUMBER='1' AIRFLOW_CTX_DAG_RUN_ID='manual__2025-05-24T21:03:17.340189+00:00'
[2025-05-24T21:03:22.760+0000] {taskinstance.py:430} INFO - ::endgroup::
[2025-05-24T21:03:22.764+0000] {etl.py:43} INFO - connected to db source
[2025-05-24T21:03:22.767+0000] {taskinstance.py:441} INFO - ::group::Post task execution logs
[2025-05-24T21:03:22.768+0000] {taskinstance.py:2890} ERROR - Task failed with exception
Traceback (most recent call last):
  File "/home/airflow/.local/lib/python3.12/site-packages/pandas/io/sql.py", line 2674, in execute
    cur.execute(sql, *args)
sqlite3.OperationalError: no such table: supplier_records

The above exception was the direct cause of the following exception:

Traceback (most recent call last):
  File "/home/airflow/.local/lib/python3.12/site-packages/airflow/models/taskinstance.py", line 465, in _execute_task
    result = _execute_callable(context=context, **execute_callable_kwargs)
             ^^^^^^^^^^^^^^^^^^^^^^^^^^^^^^^^^^^^^^^^^^^^^^^^^^^^^^^^^^^^^
  File "/home/airflow/.local/lib/python3.12/site-packages/airflow/models/taskinstance.py", line 432, in _execute_callable
    return execute_callable(context=context, **execute_callable_kwargs)
           ^^^^^^^^^^^^^^^^^^^^^^^^^^^^^^^^^^^^^^^^^^^^^^^^^^^^^^^^^^^^
  File "/home/airflow/.local/lib/python3.12/site-packages/airflow/models/baseoperator.py", line 400, in wrapper
    return func(self, *args, **kwargs)
           ^^^^^^^^^^^^^^^^^^^^^^^^^^^
  File "/home/airflow/.local/lib/python3.12/site-packages/airflow/operators/python.py", line 235, in execute
    return_value = self.execute_callable()
                   ^^^^^^^^^^^^^^^^^^^^^^^
  File "/home/airflow/.local/lib/python3.12/site-packages/airflow/operators/python.py", line 252, in execute_callable
    return self.python_callable(*self.op_args, **self.op_kwargs)
           ^^^^^^^^^^^^^^^^^^^^^^^^^^^^^^^^^^^^^^^^^^^^^^^^^^^^^
  File "/opt/airflow/dags/etl.py", line 44, in extract_sql
    df = pd.read_sql_query("SELECT * FROM supplier_records", conn)
         ^^^^^^^^^^^^^^^^^^^^^^^^^^^^^^^^^^^^^^^^^^^^^^^^^^^^^^^^^
  File "/home/airflow/.local/lib/python3.12/site-packages/pandas/io/sql.py", line 526, in read_sql_query
    return pandas_sql.read_query(
           ^^^^^^^^^^^^^^^^^^^^^^
  File "/home/airflow/.local/lib/python3.12/site-packages/pandas/io/sql.py", line 2738, in read_query
    cursor = self.execute(sql, params)
             ^^^^^^^^^^^^^^^^^^^^^^^^^
  File "/home/airflow/.local/lib/python3.12/site-packages/pandas/io/sql.py", line 2686, in execute
    raise ex from exc
pandas.errors.DatabaseError: Execution failed on sql 'SELECT * FROM supplier_records': no such table: supplier_records
[2025-05-24T21:03:22.791+0000] {taskinstance.py:1205} INFO - Marking task as UP_FOR_RETRY. dag_id=supplier_data_etl_pipeline, task_id=extract_sql_data, execution_date=20250524T210317, start_date=20250524T210322, end_date=20250524T210322
[2025-05-24T21:03:22.822+0000] {standard_task_runner.py:110} ERROR - Failed to execute job 3 for task extract_sql_data (Execution failed on sql 'SELECT * FROM supplier_records': no such table: supplier_records; 318)
[2025-05-24T21:03:22.861+0000] {local_task_job_runner.py:240} INFO - Task exited with return code 1
[2025-05-24T21:03:22.881+0000] {taskinstance.py:3482} INFO - 0 downstream tasks scheduled from follow-on schedule check
[2025-05-24T21:03:22.883+0000] {local_task_job_runner.py:222} INFO - ::endgroup::
