[2025-05-24T21:19:55.245+0000] {task_context_logger.py:104} ERROR - Executor reports task instance <TaskInstance: supplier_data_etl_pipeline.extract_csv_data manual__2025-05-24T21:19:22.630212+00:00 [queued]> finished (failed) although the task says it's queued. (Info: None) Was the task killed externally?
