[2025-05-24T21:16:33.760+0000] {local_task_job_runner.py:120} INFO - ::group::Pre task execution logs
[2025-05-24T21:16:33.788+0000] {taskinstance.py:2073} INFO - Dependencies all met for dep_context=non-requeueable deps ti=<TaskInstance: supplier_data_etl_pipeline.extract_api_data manual__2025-05-24T21:10:56.940417+00:00 [queued]>
[2025-05-24T21:16:33.794+0000] {taskinstance.py:2073} INFO - Dependencies all met for dep_context=requeueable deps ti=<TaskInstance: supplier_data_etl_pipeline.extract_api_data manual__2025-05-24T21:10:56.940417+00:00 [queued]>
[2025-05-24T21:16:33.795+0000] {taskinstance.py:2303} INFO - Starting attempt 2 of 6
[2025-05-24T21:16:33.806+0000] {taskinstance.py:2327} INFO - Executing <Task(PythonOperator): extract_api_data> on 2025-05-24 21:10:56.940417+00:00
[2025-05-24T21:16:33.831+0000] {warnings.py:110} WARNING - /home/***/.local/lib/python3.12/site-packages/***/task/task_runner/standard_task_runner.py:61: DeprecationWarning: This process (pid=535) is multi-threaded, use of fork() may lead to deadlocks in the child.
  pid = os.fork()

[2025-05-24T21:16:33.835+0000] {standard_task_runner.py:63} INFO - Started process 541 to run task
[2025-05-24T21:16:33.835+0000] {standard_task_runner.py:90} INFO - Running: ['***', 'tasks', 'run', 'supplier_data_etl_pipeline', 'extract_api_data', 'manual__2025-05-24T21:10:56.940417+00:00', '--job-id', '27', '--raw', '--subdir', 'DAGS_FOLDER/supplier_dag.py', '--cfg-path', '/tmp/tmpxbqyjawz']
[2025-05-24T21:16:33.839+0000] {standard_task_runner.py:91} INFO - Job 27: Subtask extract_api_data
[2025-05-24T21:16:33.939+0000] {task_command.py:426} INFO - Running <TaskInstance: supplier_data_etl_pipeline.extract_api_data manual__2025-05-24T21:10:56.940417+00:00 [running]> on host a7d211f7b093
[2025-05-24T21:16:34.390+0000] {taskinstance.py:2644} INFO - Exporting env vars: AIRFLOW_CTX_DAG_OWNER='***' AIRFLOW_CTX_DAG_ID='supplier_data_etl_pipeline' AIRFLOW_CTX_TASK_ID='extract_api_data' AIRFLOW_CTX_EXECUTION_DATE='2025-05-24T21:10:56.940417+00:00' AIRFLOW_CTX_TRY_NUMBER='2' AIRFLOW_CTX_DAG_RUN_ID='manual__2025-05-24T21:10:56.940417+00:00'
[2025-05-24T21:16:34.398+0000] {taskinstance.py:430} INFO - ::endgroup::
[2025-05-24T21:16:34.408+0000] {taskinstance.py:441} INFO - ::group::Post task execution logs
[2025-05-24T21:16:34.412+0000] {taskinstance.py:2890} ERROR - Task failed with exception
Traceback (most recent call last):
  File "/home/airflow/.local/lib/python3.12/site-packages/airflow/models/taskinstance.py", line 465, in _execute_task
    result = _execute_callable(context=context, **execute_callable_kwargs)
             ^^^^^^^^^^^^^^^^^^^^^^^^^^^^^^^^^^^^^^^^^^^^^^^^^^^^^^^^^^^^^
  File "/home/airflow/.local/lib/python3.12/site-packages/airflow/models/taskinstance.py", line 432, in _execute_callable
    return execute_callable(context=context, **execute_callable_kwargs)
           ^^^^^^^^^^^^^^^^^^^^^^^^^^^^^^^^^^^^^^^^^^^^^^^^^^^^^^^^^^^^
  File "/home/airflow/.local/lib/python3.12/site-packages/airflow/models/baseoperator.py", line 400, in wrapper
    return func(self, *args, **kwargs)
           ^^^^^^^^^^^^^^^^^^^^^^^^^^^
  File "/home/airflow/.local/lib/python3.12/site-packages/airflow/operators/python.py", line 235, in execute
    return_value = self.execute_callable()
                   ^^^^^^^^^^^^^^^^^^^^^^^
  File "/home/airflow/.local/lib/python3.12/site-packages/airflow/operators/python.py", line 252, in execute_callable
    return self.python_callable(*self.op_args, **self.op_kwargs)
           ^^^^^^^^^^^^^^^^^^^^^^^^^^^^^^^^^^^^^^^^^^^^^^^^^^^^^
  File "/opt/airflow/dags/etl.py", line 29, in extract_api
    Converts csv data source into a pickle binary object
         ^^^^^^^^^^^^^^^^^^^^^^^^^^^^
FileNotFoundError: [Errno 2] No such file or directory: './api_suppliers.json'
[2025-05-24T21:16:34.516+0000] {taskinstance.py:1205} INFO - Marking task as UP_FOR_RETRY. dag_id=supplier_data_etl_pipeline, task_id=extract_api_data, execution_date=20250524T211056, start_date=20250524T211633, end_date=20250524T211634
[2025-05-24T21:16:34.764+0000] {standard_task_runner.py:110} ERROR - Failed to execute job 27 for task extract_api_data ([Errno 2] No such file or directory: './api_suppliers.json'; 541)
[2025-05-24T21:16:34.826+0000] {local_task_job_runner.py:240} INFO - Task exited with return code 1
[2025-05-24T21:16:34.997+0000] {taskinstance.py:3482} INFO - 0 downstream tasks scheduled from follow-on schedule check
[2025-05-24T21:16:35.003+0000] {local_task_job_runner.py:222} INFO - ::endgroup::
