[2025-05-24T22:19:12.195+0000] {local_task_job_runner.py:120} INFO - ::group::Pre task execution logs
[2025-05-24T22:19:12.237+0000] {taskinstance.py:2073} INFO - Dependencies all met for dep_context=non-requeueable deps ti=<TaskInstance: supplier_data_etl_pipeline.upload_merged_to_s3 manual__2025-05-24T21:29:11.201967+00:00 [queued]>
[2025-05-24T22:19:12.247+0000] {taskinstance.py:2073} INFO - Dependencies all met for dep_context=requeueable deps ti=<TaskInstance: supplier_data_etl_pipeline.upload_merged_to_s3 manual__2025-05-24T21:29:11.201967+00:00 [queued]>
[2025-05-24T22:19:12.248+0000] {taskinstance.py:2303} INFO - Starting attempt 1 of 6
[2025-05-24T22:19:12.259+0000] {taskinstance.py:2327} INFO - Executing <Task(PythonOperator): upload_merged_to_s3> on 2025-05-24 21:29:11.201967+00:00
[2025-05-24T22:19:12.280+0000] {warnings.py:110} WARNING - /home/***/.local/lib/python3.12/site-packages/***/task/task_runner/standard_task_runner.py:61: DeprecationWarning: This process (pid=1566) is multi-threaded, use of fork() may lead to deadlocks in the child.
  pid = os.fork()

[2025-05-24T22:19:12.282+0000] {standard_task_runner.py:63} INFO - Started process 1577 to run task
[2025-05-24T22:19:12.283+0000] {standard_task_runner.py:90} INFO - Running: ['***', 'tasks', 'run', 'supplier_data_etl_pipeline', 'upload_merged_to_s3', 'manual__2025-05-24T21:29:11.201967+00:00', '--job-id', '124', '--raw', '--subdir', 'DAGS_FOLDER/supplier_dag.py', '--cfg-path', '/tmp/tmp4t4hovom']
[2025-05-24T22:19:12.285+0000] {standard_task_runner.py:91} INFO - Job 124: Subtask upload_merged_to_s3
[2025-05-24T22:19:12.333+0000] {task_command.py:426} INFO - Running <TaskInstance: supplier_data_etl_pipeline.upload_merged_to_s3 manual__2025-05-24T21:29:11.201967+00:00 [running]> on host a7d211f7b093
[2025-05-24T22:19:12.398+0000] {taskinstance.py:2644} INFO - Exporting env vars: AIRFLOW_CTX_DAG_OWNER='***' AIRFLOW_CTX_DAG_ID='supplier_data_etl_pipeline' AIRFLOW_CTX_TASK_ID='upload_merged_to_s3' AIRFLOW_CTX_EXECUTION_DATE='2025-05-24T21:29:11.201967+00:00' AIRFLOW_CTX_TRY_NUMBER='1' AIRFLOW_CTX_DAG_RUN_ID='manual__2025-05-24T21:29:11.201967+00:00'
[2025-05-24T22:19:12.401+0000] {taskinstance.py:430} INFO - ::endgroup::
[2025-05-24T22:19:12.408+0000] {etl.py:137} ERROR - Failed to create AWS session: 'Variable aws_access_key_id does not exist'
[2025-05-24T22:19:12.481+0000] {etl.py:181} ERROR - Unexpected error during S3 upload: Unable to locate credentials
[2025-05-24T22:19:12.481+0000] {taskinstance.py:441} INFO - ::group::Post task execution logs
[2025-05-24T22:19:12.482+0000] {taskinstance.py:2890} ERROR - Task failed with exception
Traceback (most recent call last):
  File "/home/airflow/.local/lib/python3.12/site-packages/airflow/models/taskinstance.py", line 465, in _execute_task
    result = _execute_callable(context=context, **execute_callable_kwargs)
             ^^^^^^^^^^^^^^^^^^^^^^^^^^^^^^^^^^^^^^^^^^^^^^^^^^^^^^^^^^^^^
  File "/home/airflow/.local/lib/python3.12/site-packages/airflow/models/taskinstance.py", line 432, in _execute_callable
    return execute_callable(context=context, **execute_callable_kwargs)
           ^^^^^^^^^^^^^^^^^^^^^^^^^^^^^^^^^^^^^^^^^^^^^^^^^^^^^^^^^^^^
  File "/home/airflow/.local/lib/python3.12/site-packages/airflow/models/baseoperator.py", line 400, in wrapper
    return func(self, *args, **kwargs)
           ^^^^^^^^^^^^^^^^^^^^^^^^^^^
  File "/home/airflow/.local/lib/python3.12/site-packages/airflow/operators/python.py", line 235, in execute
    return_value = self.execute_callable()
                   ^^^^^^^^^^^^^^^^^^^^^^^
  File "/home/airflow/.local/lib/python3.12/site-packages/airflow/operators/python.py", line 252, in execute_callable
    return self.python_callable(*self.op_args, **self.op_kwargs)
           ^^^^^^^^^^^^^^^^^^^^^^^^^^^^^^^^^^^^^^^^^^^^^^^^^^^^^
  File "/opt/airflow/dags/etl.py", line 169, in upload_to_s3
    s3.upload_file(local_path, bucket, key)
  File "/home/airflow/.local/lib/python3.12/site-packages/botocore/context.py", line 123, in wrapper
    return func(*args, **kwargs)
           ^^^^^^^^^^^^^^^^^^^^^
  File "/home/airflow/.local/lib/python3.12/site-packages/boto3/s3/inject.py", line 175, in upload_file
    return transfer.upload_file(
           ^^^^^^^^^^^^^^^^^^^^^
  File "/home/airflow/.local/lib/python3.12/site-packages/boto3/s3/transfer.py", line 372, in upload_file
    future.result()
  File "/home/airflow/.local/lib/python3.12/site-packages/s3transfer/futures.py", line 111, in result
    return self._coordinator.result()
           ^^^^^^^^^^^^^^^^^^^^^^^^^^
  File "/home/airflow/.local/lib/python3.12/site-packages/s3transfer/futures.py", line 287, in result
    raise self._exception
  File "/home/airflow/.local/lib/python3.12/site-packages/s3transfer/tasks.py", line 142, in __call__
    return self._execute_main(kwargs)
           ^^^^^^^^^^^^^^^^^^^^^^^^^^
  File "/home/airflow/.local/lib/python3.12/site-packages/s3transfer/tasks.py", line 165, in _execute_main
    return_value = self._main(**kwargs)
                   ^^^^^^^^^^^^^^^^^^^^
  File "/home/airflow/.local/lib/python3.12/site-packages/s3transfer/upload.py", line 796, in _main
    client.put_object(Bucket=bucket, Key=key, Body=body, **extra_args)
  File "/home/airflow/.local/lib/python3.12/site-packages/botocore/client.py", line 595, in _api_call
    return self._make_api_call(operation_name, kwargs)
           ^^^^^^^^^^^^^^^^^^^^^^^^^^^^^^^^^^^^^^^^^^^
  File "/home/airflow/.local/lib/python3.12/site-packages/botocore/context.py", line 123, in wrapper
    return func(*args, **kwargs)
           ^^^^^^^^^^^^^^^^^^^^^
  File "/home/airflow/.local/lib/python3.12/site-packages/botocore/client.py", line 1040, in _make_api_call
    http, parsed_response = self._make_request(
                            ^^^^^^^^^^^^^^^^^^^
  File "/home/airflow/.local/lib/python3.12/site-packages/botocore/client.py", line 1064, in _make_request
    return self._endpoint.make_request(operation_model, request_dict)
           ^^^^^^^^^^^^^^^^^^^^^^^^^^^^^^^^^^^^^^^^^^^^^^^^^^^^^^^^^^
  File "/home/airflow/.local/lib/python3.12/site-packages/botocore/endpoint.py", line 119, in make_request
    return self._send_request(request_dict, operation_model)
           ^^^^^^^^^^^^^^^^^^^^^^^^^^^^^^^^^^^^^^^^^^^^^^^^^
  File "/home/airflow/.local/lib/python3.12/site-packages/botocore/endpoint.py", line 196, in _send_request
    request = self.create_request(request_dict, operation_model)
              ^^^^^^^^^^^^^^^^^^^^^^^^^^^^^^^^^^^^^^^^^^^^^^^^^^
  File "/home/airflow/.local/lib/python3.12/site-packages/botocore/endpoint.py", line 132, in create_request
    self._event_emitter.emit(
  File "/home/airflow/.local/lib/python3.12/site-packages/botocore/hooks.py", line 412, in emit
    return self._emitter.emit(aliased_event_name, **kwargs)
           ^^^^^^^^^^^^^^^^^^^^^^^^^^^^^^^^^^^^^^^^^^^^^^^^
  File "/home/airflow/.local/lib/python3.12/site-packages/botocore/hooks.py", line 256, in emit
    return self._emit(event_name, kwargs)
           ^^^^^^^^^^^^^^^^^^^^^^^^^^^^^^
  File "/home/airflow/.local/lib/python3.12/site-packages/botocore/hooks.py", line 239, in _emit
    response = handler(**kwargs)
               ^^^^^^^^^^^^^^^^^
  File "/home/airflow/.local/lib/python3.12/site-packages/botocore/signers.py", line 106, in handler
    return self.sign(operation_name, request)
           ^^^^^^^^^^^^^^^^^^^^^^^^^^^^^^^^^^
  File "/home/airflow/.local/lib/python3.12/site-packages/botocore/signers.py", line 198, in sign
    auth.add_auth(request)
  File "/home/airflow/.local/lib/python3.12/site-packages/botocore/auth.py", line 424, in add_auth
    raise NoCredentialsError()
botocore.exceptions.NoCredentialsError: Unable to locate credentials
[2025-05-24T22:19:12.498+0000] {taskinstance.py:1205} INFO - Marking task as UP_FOR_RETRY. dag_id=supplier_data_etl_pipeline, task_id=upload_merged_to_s3, execution_date=20250524T212911, start_date=20250524T221912, end_date=20250524T221912
[2025-05-24T22:19:12.510+0000] {standard_task_runner.py:110} ERROR - Failed to execute job 124 for task upload_merged_to_s3 (Unable to locate credentials; 1577)
[2025-05-24T22:19:12.546+0000] {local_task_job_runner.py:240} INFO - Task exited with return code 1
[2025-05-24T22:19:12.559+0000] {taskinstance.py:3482} INFO - 0 downstream tasks scheduled from follow-on schedule check
[2025-05-24T22:19:12.560+0000] {local_task_job_runner.py:222} INFO - ::endgroup::
