[2025-05-24T22:18:16.167+0000] {local_task_job_runner.py:120} INFO - ::group::Pre task execution logs
[2025-05-24T22:18:16.180+0000] {taskinstance.py:2073} INFO - Dependencies all met for dep_context=non-requeueable deps ti=<TaskInstance: supplier_data_etl_pipeline.transform_and_merge manual__2025-05-24T21:29:11.201967+00:00 [queued]>
[2025-05-24T22:18:16.184+0000] {taskinstance.py:2073} INFO - Dependencies all met for dep_context=requeueable deps ti=<TaskInstance: supplier_data_etl_pipeline.transform_and_merge manual__2025-05-24T21:29:11.201967+00:00 [queued]>
[2025-05-24T22:18:16.184+0000] {taskinstance.py:2303} INFO - Starting attempt 1 of 6
[2025-05-24T22:18:16.190+0000] {taskinstance.py:2327} INFO - Executing <Task(PythonOperator): transform_and_merge> on 2025-05-24 21:29:11.201967+00:00
[2025-05-24T22:18:16.198+0000] {warnings.py:110} WARNING - /home/***/.local/lib/python3.12/site-packages/***/task/task_runner/standard_task_runner.py:61: DeprecationWarning: This process (pid=1551) is multi-threaded, use of fork() may lead to deadlocks in the child.
  pid = os.fork()

[2025-05-24T22:18:16.199+0000] {standard_task_runner.py:63} INFO - Started process 1553 to run task
[2025-05-24T22:18:16.199+0000] {standard_task_runner.py:90} INFO - Running: ['***', 'tasks', 'run', 'supplier_data_etl_pipeline', 'transform_and_merge', 'manual__2025-05-24T21:29:11.201967+00:00', '--job-id', '122', '--raw', '--subdir', 'DAGS_FOLDER/supplier_dag.py', '--cfg-path', '/tmp/tmpnrtmgz7g']
[2025-05-24T22:18:16.200+0000] {standard_task_runner.py:91} INFO - Job 122: Subtask transform_and_merge
[2025-05-24T22:18:16.239+0000] {task_command.py:426} INFO - Running <TaskInstance: supplier_data_etl_pipeline.transform_and_merge manual__2025-05-24T21:29:11.201967+00:00 [running]> on host a7d211f7b093
[2025-05-24T22:18:16.283+0000] {taskinstance.py:2644} INFO - Exporting env vars: AIRFLOW_CTX_DAG_OWNER='***' AIRFLOW_CTX_DAG_ID='supplier_data_etl_pipeline' AIRFLOW_CTX_TASK_ID='transform_and_merge' AIRFLOW_CTX_EXECUTION_DATE='2025-05-24T21:29:11.201967+00:00' AIRFLOW_CTX_TRY_NUMBER='1' AIRFLOW_CTX_DAG_RUN_ID='manual__2025-05-24T21:29:11.201967+00:00'
[2025-05-24T22:18:16.285+0000] {taskinstance.py:430} INFO - ::endgroup::
[2025-05-24T22:18:16.285+0000] {taskinstance.py:441} INFO - ::group::Post task execution logs
[2025-05-24T22:18:16.286+0000] {taskinstance.py:2890} ERROR - Task failed with exception
Traceback (most recent call last):
  File "/home/airflow/.local/lib/python3.12/site-packages/airflow/models/taskinstance.py", line 465, in _execute_task
    result = _execute_callable(context=context, **execute_callable_kwargs)
             ^^^^^^^^^^^^^^^^^^^^^^^^^^^^^^^^^^^^^^^^^^^^^^^^^^^^^^^^^^^^^
  File "/home/airflow/.local/lib/python3.12/site-packages/airflow/models/taskinstance.py", line 432, in _execute_callable
    return execute_callable(context=context, **execute_callable_kwargs)
           ^^^^^^^^^^^^^^^^^^^^^^^^^^^^^^^^^^^^^^^^^^^^^^^^^^^^^^^^^^^^
  File "/home/airflow/.local/lib/python3.12/site-packages/airflow/models/baseoperator.py", line 400, in wrapper
    return func(self, *args, **kwargs)
           ^^^^^^^^^^^^^^^^^^^^^^^^^^^
  File "/home/airflow/.local/lib/python3.12/site-packages/airflow/operators/python.py", line 235, in execute
    return_value = self.execute_callable()
                   ^^^^^^^^^^^^^^^^^^^^^^^
  File "/home/airflow/.local/lib/python3.12/site-packages/airflow/operators/python.py", line 252, in execute_callable
    return self.python_callable(*self.op_args, **self.op_kwargs)
           ^^^^^^^^^^^^^^^^^^^^^^^^^^^^^^^^^^^^^^^^^^^^^^^^^^^^^
  File "/opt/airflow/dags/etl.py", line 90, in transform_and_merge
    df_csv = pd.read_pickle("./tmp/df_csv.pkl")
             ^^^^^^^^^^^^^^^^^^^^^^^^^^^^^^^^^^
  File "/home/airflow/.local/lib/python3.12/site-packages/pandas/io/pickle.py", line 185, in read_pickle
    with get_handle(
         ^^^^^^^^^^^
  File "/home/airflow/.local/lib/python3.12/site-packages/pandas/io/common.py", line 882, in get_handle
    handle = open(handle, ioargs.mode)
             ^^^^^^^^^^^^^^^^^^^^^^^^^
FileNotFoundError: [Errno 2] No such file or directory: './tmp/df_csv.pkl'
[2025-05-24T22:18:16.293+0000] {taskinstance.py:1205} INFO - Marking task as UP_FOR_RETRY. dag_id=supplier_data_etl_pipeline, task_id=transform_and_merge, execution_date=20250524T212911, start_date=20250524T221816, end_date=20250524T221816
[2025-05-24T22:18:16.299+0000] {standard_task_runner.py:110} ERROR - Failed to execute job 122 for task transform_and_merge ([Errno 2] No such file or directory: './tmp/df_csv.pkl'; 1553)
[2025-05-24T22:18:16.341+0000] {local_task_job_runner.py:240} INFO - Task exited with return code 1
[2025-05-24T22:18:16.354+0000] {taskinstance.py:3482} INFO - 0 downstream tasks scheduled from follow-on schedule check
[2025-05-24T22:18:16.355+0000] {local_task_job_runner.py:222} INFO - ::endgroup::
