[2025-05-24T22:31:38.630+0000] {task_context_logger.py:104} ERROR - Executor reports task instance <TaskInstance: supplier_data_etl_pipeline.extract_api_data manual__2025-05-24T21:17:11.637733+00:00 [queued]> finished (failed) although the task says it's queued. (Info: None) Was the task killed externally?
