[2025-05-24T22:31:40.198+0000] {task_context_logger.py:104} ERROR - Executor reports task instance <TaskInstance: supplier_data_etl_pipeline.upload_merged_to_s3 manual__2025-05-24T21:08:13.436954+00:00 [queued]> finished (failed) although the task says it's queued. (Info: None) Was the task killed externally?
